<mujoco model="Z01">
  <compiler angle="radian" meshdir="assets/" autolimits="true"/>
  <statistic center="1.0 0.7 1.0" extent="0.8"/>
  <option integrator="implicitfast"/>
  <default>
    <!-- <joint damping="0.001" armature="0.01" frictionloss="0.1"/> -->
    <geom contype="2" conaffinity="1"/>
  </default>
  <visual>
    <headlight diffuse="0.6 0.6 0.6" ambient="0.1 0.1 0.1" specular="0.9 0.9 0.9"/>
    <rgba haze="0.15 0.25 0.35 1"/>
    <global azimuth="-140" elevation="-20"/>
  </visual>

  <asset>
    <mesh name="base_link" file="base_link.STL"/>
    <mesh name="left_hip_pitch_link" file="left_hip_pitch_link.STL"/>
    <mesh name="left_hip_roll_link" file="left_hip_roll_link.STL"/>
    <mesh name="left_hip_yaw_link" file="left_hip_yaw_link.STL"/>
    <mesh name="left_knee_pitch_link" file="left_knee_pitch_link.STL"/>
    <mesh name="left_ankle_pitch_link" file="left_ankle_pitch_link.STL"/>
    <mesh name="left_ankle_roll_link" file="left_ankle_roll_link.STL"/>
    <mesh name="right_hip_pitch_link" file="right_hip_pitch_link.STL"/>
    <mesh name="right_hip_roll_link" file="right_hip_roll_link.STL"/>
    <mesh name="right_hip_yaw_link" file="right_hip_yaw_link.STL"/>
    <mesh name="right_knee_pitch_link" file="right_knee_pitch_link.STL"/>
    <mesh name="right_ankle_pitch_link" file="right_ankle_pitch_link.STL"/>
    <mesh name="right_ankle_roll_link" file="right_ankle_roll_link.STL"/>
    <mesh name="waist_yaw_link" file="waist_yaw_link.STL"/>
    <mesh name="waist_pitch_link" file="waist_pitch_link.STL"/>
    <mesh name="left_shoulder_pitch_link" file="left_shoulder_pitch_link.STL"/>
    <mesh name="left_shoulder_roll_link" file="left_shoulder_roll_link.STL"/>
    <mesh name="left_elbow_yaw_link" file="left_elbow_yaw_link.STL"/>
    <mesh name="left_elbow_pitch_link" file="left_elbow_pitch_link.STL"/>
    <mesh name="left_wrist_yaw_link" file="left_wrist_yaw_link.STL"/>
    <mesh name="right_shoulder_pitch_link" file="right_shoulder_pitch_link.STL"/>
    <mesh name="right_shoulder_roll_link" file="right_shoulder_roll_link.STL"/>
    <mesh name="right_elbow_yaw_link" file="right_elbow_yaw_link.STL"/>
    <mesh name="right_elbow_pitch_link" file="right_elbow_pitch_link.STL"/>
    <mesh name="right_wrist_yaw_link" file="right_wrist_yaw_link.STL"/>
    <mesh name="head_yaw_link" file="head_yaw_link.STL"/>
    <mesh name="head_pitch_link" file="head_pitch_link.STL"/>
    <mesh name="head_roll_link" file="head_roll_link.STL"/>
  </asset>

  <worldbody>
    <body name="base_link">
      <inertial pos="-5.2031e-05 -2.0533e-06 0.0020481" quat="0.705827 0.708372 -0.00255144 0.00343983" mass="5.0523" diaginertia="0.0188432 0.0160028 0.0124069"/>
      <joint name="floating_base_joint" type="free"/>
      <geom type="mesh" contype="0" conaffinity="0" group="1" density="0" rgba="0.75294 0.75294 0.75294 1" mesh="base_link"/>
      <geom name="base_link_collision" type="mesh" rgba="0.75294 0.75294 0.75294 1" mesh="base_link"/>
      <site name="base_imu_site" pos="0 0 0" size="0.01"/>
      <body name="left_hip_pitch_link" pos="0 0.0959544 -0.0322644" quat="0.92388 -0.382683 0 0">
        <inertial pos="0.00545388 0.0462565 7.28028e-05" quat="0.999352 0.0142492 0.00230312 0.0329881" mass="2.13147" diaginertia="0.00334989 0.00265389 0.00222559"/>
        <joint name="left_hip_pitch" pos="0 0 0" axis="0 1 0" range="-1.57 1.57" actuatorfrcrange="-330 330"/>
        <geom type="mesh" contype="0" conaffinity="0" group="1" density="0" rgba="0.752941 0.752941 0.752941 1" mesh="left_hip_pitch_link"/>
        <geom name="left_hip_pitch_link_collision" type="mesh" rgba="0.752941 0.752941 0.752941 1" mesh="left_hip_pitch_link"/>
        <body name="left_hip_roll_link" pos="0 0.0593 0" quat="0.92388 0.382683 0 0">
          <inertial pos="-0.000641176 0.00052454 -0.0618598" quat="0.99998 0.00342601 0.00520615 0.00104279" mass="3.11222" diaginertia="0.00735623 0.00586125 0.0038922"/>
          <joint name="left_hip_roll" pos="0 0 0" axis="1 0 0" range="-0.17 0.78" actuatorfrcrange="-70 70"/>
          <geom type="mesh" contype="0" conaffinity="0" group="1" density="0" rgba="0.752941 0.752941 0.752941 1" mesh="left_hip_roll_link"/>
          <geom name="left_hip_roll_link_collision" type="mesh" rgba="0.752941 0.752941 0.752941 1" mesh="left_hip_roll_link"/>
          <body name="left_hip_yaw_link" pos="0 0 -0.119">
            <inertial pos="0.00420803 0.0049643 -0.149584" quat="0.709649 0.0185723 0.0248893 0.703871" mass="5.39307" diaginertia="0.0522609 0.0466793 0.00861801"/>
            <joint name="left_hip_yaw" pos="0 0 0" axis="0 0 1" range="-0.52 0.52" actuatorfrcrange="-70 70"/>
            <geom type="mesh" contype="0" conaffinity="0" group="1" density="0" rgba="0.752941 0.752941 0.752941 1" mesh="left_hip_yaw_link"/>
            <geom name="left_hip_yaw_link_collision" type="mesh" rgba="0.752941 0.752941 0.752941 1" mesh="left_hip_yaw_link"/>
            <body name="left_knee_pitch_link" pos="0 0 -0.363">
              <inertial pos="-0.00317674 0.000243977 -0.166286" quat="0.705967 -0.00249688 -0.00197445 0.708237" mass="4.85718" diaginertia="0.0259128 0.0251601 0.00202454"/>
              <joint name="left_knee_pitch" pos="0 0 0" axis="0 1 0" range="-1.57 0" actuatorfrcrange="-330 330"/>
              <geom type="mesh" contype="0" conaffinity="0" group="1" density="0" rgba="0.752941 0.752941 0.752941 1" mesh="left_knee_pitch_link"/>
              <geom name="left_knee_pitch_link_collision" type="mesh" rgba="0.752941 0.752941 0.752941 1" mesh="left_knee_pitch_link"/>
              <body name="left_ankle_pitch_link" pos="0 0 -0.374">
                <inertial pos="2.08791e-09 1.7862e-09 0" quat="0 0.707107 0 0.707107" mass="0.125704" diaginertia="3.44419e-05 2.12238e-05 1.66569e-05"/>
                <joint name="left_ankle_pitch" pos="0 0 0" axis="0 1 0" range="-0.68 0.68" actuatorfrcrange="-75 75"/>
                <geom type="mesh" contype="0" conaffinity="0" group="1" density="0" rgba="0.752941 0.752941 0.752941 1" mesh="left_ankle_pitch_link"/>
                <geom name="left_ankle_pitch_link_collision" type="mesh" rgba="0.752941 0.752941 0.752941 1" mesh="left_ankle_pitch_link"/>
                <body name="left_ankle_roll_link">
                  <inertial pos="-0.0104011 0.000724835 -0.0257983" quat="-0.00175044 0.699096 0.00517645 0.715007" mass="0.957892" diaginertia="0.00231277 0.00204591 0.000410361"/>
                  <joint name="left_ankle_roll" pos="0 0 0" axis="1 0 0" range="-0.25 0.25" actuatorfrcrange="-75 75"/>
                  <geom type="mesh" contype="0" conaffinity="0" group="1" density="0" rgba="0.752941 0.752941 0.752941 1" mesh="left_ankle_roll_link"/>
                  <geom name="left_ankle_roll_link_collision" type="mesh" rgba="0.752941 0.752941 0.752941 1" mesh="left_ankle_roll_link"/>
                  <site name="left_ankle_site" pos="0 0 0" size="0.01"/>
                </body>
              </body>
            </body>
          </body>
        </body>
      </body>
      <body name="right_hip_pitch_link" pos="0 -0.0959544 -0.0322644" quat="0.92388 0.382683 0 0">
        <inertial pos="0.00542316 -0.0462208 7.08223e-05" quat="0.999354 -0.0119464 0.00223516 -0.0338194" mass="2.13366" diaginertia="0.00335098 0.0026569 0.00222699"/>
        <joint name="right_hip_pitch" pos="0 0 0" axis="0 1 0" range="-1.57 1.57" actuatorfrcrange="-330 330"/>
        <geom type="mesh" contype="0" conaffinity="0" group="1" density="0" rgba="0.752941 0.752941 0.752941 1" mesh="right_hip_pitch_link"/>
        <geom name="right_hip_pitch_link_collision" type="mesh" rgba="0.752941 0.752941 0.752941 1" mesh="right_hip_pitch_link"/>
        <body name="right_hip_roll_link" pos="0 -0.0593 0" quat="0.92388 -0.382683 0 0">
          <inertial pos="-0.000641017 -0.000524617 -0.0618597" quat="0.99998 -0.00342453 0.00520239 -0.000641927" mass="3.11226" diaginertia="0.00735686 0.00586083 0.00389221"/>
          <joint name="right_hip_roll" pos="0 0 0" axis="1 0 0" range="-0.78 0.17" actuatorfrcrange="-70 70"/>
          <geom type="mesh" contype="0" conaffinity="0" group="1" density="0" rgba="0.752941 0.752941 0.752941 1" mesh="right_hip_roll_link"/>
          <geom name="right_hip_roll_link_collision" type="mesh" rgba="0.752941 0.752941 0.752941 1" mesh="right_hip_roll_link"/>
          <body name="right_hip_yaw_link" pos="0 0 -0.119">
            <inertial pos="0.00420844 -0.00496649 -0.149581" quat="0.703874 0.0248999 0.0185816 0.709645" mass="5.39294" diaginertia="0.0522607 0.0466788 0.00861846"/>
            <joint name="right_hip_yaw" pos="0 0 0" axis="0 0 1" range="-0.52 0.52" actuatorfrcrange="-70 70"/>
            <geom type="mesh" contype="0" conaffinity="0" group="1" density="0" rgba="0.752941 0.752941 0.752941 1" mesh="right_hip_yaw_link"/>
            <geom name="right_hip_yaw_link_collision" type="mesh" rgba="0.752941 0.752941 0.752941 1" mesh="right_hip_yaw_link"/>
            <body name="right_knee_pitch_link" pos="0 0 -0.363">
              <inertial pos="-0.00317261 -0.000244187 -0.166286" quat="0.708245 -0.00197035 -0.00248779 0.70596" mass="4.85728" diaginertia="0.0259141 0.0251615 0.00202439"/>
              <joint name="right_knee_pitch" pos="0 0 0" axis="0 1 0" range="0 1.57" actuatorfrcrange="-330 330"/>
              <geom type="mesh" contype="0" conaffinity="0" group="1" density="0" rgba="0.752941 0.752941 0.752941 1" mesh="right_knee_pitch_link"/>
              <geom name="right_knee_pitch_link_collision" type="mesh" rgba="0.752941 0.752941 0.752941 1" mesh="right_knee_pitch_link"/>
              <body name="right_ankle_pitch_link" pos="0 0 -0.374">
                <inertial pos="2.08789e-09 -1.68818e-09 0" quat="0 0.707107 0 0.707107" mass="0.125704" diaginertia="3.44419e-05 2.12238e-05 1.66569e-05"/>
                <joint name="right_ankle_pitch" pos="0 0 0" axis="0 1 0" range="-0.68 0.68" actuatorfrcrange="-75 75"/>
                <geom type="mesh" contype="0" conaffinity="0" group="1" density="0" rgba="0.752941 0.752941 0.752941 1" mesh="right_ankle_pitch_link"/>
                <geom name="right_ankle_pitch_link_collision" type="mesh" rgba="0.752941 0.752941 0.752941 1" mesh="right_ankle_pitch_link"/>
                <body name="right_ankle_roll_link">
                  <inertial pos="-0.0104043 -0.000724471 -0.0257983" quat="0.00175308 0.699094 -0.00518639 0.715009" mass="0.957884" diaginertia="0.00231219 0.00204533 0.000410363"/>
                  <joint name="right_ankle_roll" pos="0 0 0" axis="1 0 0" range="-0.25 0.25" actuatorfrcrange="-75 75"/>
                  <geom type="mesh" contype="0" conaffinity="0" group="1" density="0" rgba="0.752941 0.752941 0.752941 1" mesh="right_ankle_roll_link"/>
                  <geom name="right_ankle_roll_link_collision" type="mesh" rgba="0.752941 0.752941 0.752941 1" mesh="right_ankle_roll_link"/>
                  <site name="right_ankle_site" pos="0 0 0" size="0.01"/>
                </body>
              </body>
            </body>
          </body>
        </body>
      </body>
      <body name="waist_yaw_link" pos="0 0 0.109061">
        <inertial pos="0.00064155 -0.0017701 0.047829" quat="0.698929 0.142762 -0.123809 0.689774" mass="0.79875" diaginertia="0.000917587 0.000813453 0.00071491"/>
        <joint name="waist_yaw" pos="0 0 0" axis="0 0 1" range="-1.57 1.57" actuatorfrcrange="-102 102"/>
        <geom type="mesh" contype="0" conaffinity="0" group="1" density="0" rgba="0.75294 0.75294 0.75294 1" mesh="waist_yaw_link"/>
        <geom name="waist_yaw_link_collision" type="mesh" rgba="0.75294 0.75294 0.75294 1" mesh="waist_yaw_link"/>
        <body name="waist_pitch_link" pos="0 0 0.055">
          <inertial pos="-0.00180836 0.00191888 0.196273" quat="0.500421 0.501947 -0.499168 0.498458" mass="14.6195" diaginertia="0.0448734 0.0369676 0.0223867"/>
          <joint name="waist_pitch" pos="0 0 0" axis="0 1 0" range="-0.78 0.78" actuatorfrcrange="-102 102"/>
          <geom type="mesh" contype="0" conaffinity="0" group="1" density="0" rgba="0.752941 0.752941 0.752941 1" mesh="waist_pitch_link"/>
          <geom name="waist_pitch_link_collision" type="mesh" rgba="0.752941 0.752941 0.752941 1" mesh="waist_pitch_link"/>
          <body name="left_shoulder_pitch_link" pos="0 0.164 0.2634">
            <inertial pos="-0.00146791 0.036516 -0.00015766" quat="0.704665 0.708713 0.0245326 0.023894" mass="0.310709" diaginertia="0.000378752 0.000298216 0.000273607"/>
            <joint name="left_shoulder_pitch" pos="0 0 0" axis="0 1 0" range="-2.09 1.57" actuatorfrcrange="-66 66"/>
            <geom type="mesh" contype="0" conaffinity="0" group="1" density="0" rgba="0.752941 0.752941 0.752941 1" mesh="left_shoulder_pitch_link"/>
            <geom name="left_shoulder_pitch_link_collision" type="mesh" rgba="0.752941 0.752941 0.752941 1" mesh="left_shoulder_pitch_link"/>
            <body name="left_shoulder_roll_link" pos="0 0.058 0" quat="0.996195 0.0871557 0 0">
              <inertial pos="0.00112649 0.00104716 -0.0410045" quat="0.990167 -0.00534074 -0.13944 0.00990619" mass="0.486656" diaginertia="0.00104983 0.000968381 0.00035721"/>
              <joint name="left_shoulder_roll" pos="0 0 0" axis="1 0 0" range="-0.1 2.96" actuatorfrcrange="-66 66"/>
              <geom type="mesh" contype="0" conaffinity="0" group="1" density="0" rgba="0.752941 0.752941 0.752941 1" mesh="left_shoulder_roll_link"/>
              <geom name="left_shoulder_roll_link_collision" type="mesh" rgba="0.752941 0.752941 0.752941 1" mesh="left_shoulder_roll_link"/>
              <body name="left_elbow_yaw_link" pos="0 0 -0.1281">
                <inertial pos="-0.00554941 -0.000271139 -0.089972" quat="0.823299 -0.0172167 -0.00178683 0.567343" mass="0.410618" diaginertia="0.00177393 0.001768 0.00031978"/>
                <joint name="left_elbow_yaw" pos="0 0 0" axis="0 0 1" range="-1.57 1.57" actuatorfrcrange="-34 34"/>
                <geom type="mesh" contype="0" conaffinity="0" group="1" density="0" rgba="0.752941 0.752941 0.752941 1" mesh="left_elbow_yaw_link"/>
                <geom name="left_elbow_yaw_link_collision" type="mesh" rgba="0.752941 0.752941 0.752941 1" mesh="left_elbow_yaw_link"/>
                <body name="left_elbow_pitch_link" pos="0 0 -0.1609">
                  <inertial pos="-6.26968e-09 0.000558933 -0.0598087" quat="0.70249 0.0808427 -0.0808395 0.702451" mass="0.514285" diaginertia="0.00080022 0.000750395 0.000252897"/>
                  <joint name="left_elbow_pitch" pos="0 0 0" axis="0 1 0" range="-2.27 1.57" actuatorfrcrange="-34 34"/>
                  <geom type="mesh" contype="0" conaffinity="0" group="1" density="0" rgba="0.752941 0.752941 0.752941 1" mesh="left_elbow_pitch_link"/>
                  <geom name="left_elbow_pitch_link_collision" type="mesh" rgba="0.752941 0.752941 0.752941 1" mesh="left_elbow_pitch_link"/>
                  <body name="left_wrist_yaw_link" pos="0 0 -0.1415">
                    <inertial pos="5.68108e-12 0 -0.035612" mass="0.200063" diaginertia="0.000205855 0.000205855 0.000110163"/>
                    <joint name="left_wrist_yaw" pos="0 0 0" axis="0 0 1" range="-1.57 1.57" actuatorfrcrange="-11 11"/>
                    <geom type="mesh" contype="0" conaffinity="0" group="1" density="0" rgba="0.752941 0.752941 0.752941 1" mesh="left_wrist_yaw_link"/>
                    <geom name="left_wrist_yaw_link_collision" type="mesh" rgba="0.752941 0.752941 0.752941 1" mesh="left_wrist_yaw_link"/>
                  </body>
                </body>
              </body>
            </body>
          </body>
          <body name="right_shoulder_pitch_link" pos="0 -0.164 0.2634">
            <inertial pos="-0.00146791 -0.036516 0.00015766" quat="0.704665 0.708713 -0.0245326 -0.023894" mass="0.310709" diaginertia="0.000378752 0.000298216 0.000273607"/>
            <joint name="right_shoulder_pitch" pos="0 0 0" axis="0 1 0" range="-1.57 2.27" actuatorfrcrange="-66 66"/>
            <geom type="mesh" contype="0" conaffinity="0" group="1" density="0" rgba="0.752941 0.752941 0.752941 1" mesh="right_shoulder_pitch_link"/>
            <geom name="right_shoulder_pitch_link_collision" type="mesh" rgba="0.752941 0.752941 0.752941 1" mesh="right_shoulder_pitch_link"/>
            <body name="right_shoulder_roll_link" pos="0 -0.058 0" quat="0.996195 -0.0871557 0 0">
              <inertial pos="0.0011264 -0.00101547 -0.0410045" quat="0.990167 0.00534115 -0.139439 -0.00990621" mass="0.486655" diaginertia="0.00104983 0.000968379 0.00035721"/>
              <joint name="right_shoulder_roll" pos="0 0 0" axis="1 0 0" range="-2.96 0.1" actuatorfrcrange="-66 66"/>
              <geom type="mesh" contype="0" conaffinity="0" group="1" density="0" rgba="0.752941 0.752941 0.752941 1" mesh="right_shoulder_roll_link"/>
              <geom name="right_shoulder_roll_link_collision" type="mesh" rgba="0.752941 0.752941 0.752941 1" mesh="right_shoulder_roll_link"/>
              <body name="right_elbow_yaw_link" pos="0 5e-05 -0.1281">
                <inertial pos="-0.0056495 0.000271246 -0.0903461" quat="0.560412 -0.00164475 -0.0171167 0.828036" mass="0.41062" diaginertia="0.00177396 0.00176842 0.000319338"/>
                <joint name="right_elbow_yaw" pos="0 0 0" axis="0 0 1" range="-1.57 1.57" actuatorfrcrange="-34 34"/>
                <geom type="mesh" contype="0" conaffinity="0" group="1" density="0" rgba="0.752941 0.752941 0.752941 1" mesh="right_elbow_yaw_link"/>
                <geom name="right_elbow_yaw_link_collision" type="mesh" rgba="0.752941 0.752941 0.752941 1" mesh="right_elbow_yaw_link"/>
                <body name="right_elbow_pitch_link" pos="0 0 -0.1609">
                  <inertial pos="4.73962e-09 -0.000558934 -0.0598087" quat="0.70249 -0.0808428 0.0808395 0.702451" mass="0.514285" diaginertia="0.00080022 0.000750395 0.000252897"/>
                  <joint name="right_elbow_pitch" pos="0 0 0" axis="0 1 0" range="-1.57 2.27" actuatorfrcrange="-34 34"/>
                  <geom type="mesh" contype="0" conaffinity="0" group="1" density="0" rgba="0.752941 0.752941 0.752941 1" mesh="right_elbow_pitch_link"/>
                  <geom name="right_elbow_pitch_link_collision" type="mesh" rgba="0.752941 0.752941 0.752941 1" mesh="right_elbow_pitch_link"/>
                  <body name="right_wrist_yaw_link" pos="0 0 -0.1415">
                    <inertial pos="-4.92808e-12 0 -0.035612" mass="0.200063" diaginertia="0.000205855 0.000205855 0.000110163"/>
                    <joint name="right_wrist_yaw" pos="0 0 0" axis="0 0 1" range="-1.57 1.57" actuatorfrcrange="-11 11"/>
                    <geom type="mesh" contype="0" conaffinity="0" group="1" density="0" rgba="0.752941 0.752941 0.752941 1" mesh="right_wrist_yaw_link"/>
                    <geom name="right_wrist_yaw_link_collision" type="mesh" rgba="0.752941 0.752941 0.752941 1" mesh="right_wrist_yaw_link"/>
                  </body>
                </body>
              </body>
            </body>
          </body>
          <body name="head_yaw_link" pos="0 0 0.332">
            <inertial pos="0 -0.0227008 0.0432654" quat="0.691758 -0.14653 0.14653 0.691758" mass="0.258664" diaginertia="0.000130167 0.000129656 6.97225e-05"/>
            <joint name="head_yaw" pos="0 0 0" axis="0 0 -1" range="-1.57 1.57" actuatorfrcrange="-11 11"/>
            <geom type="mesh" contype="0" conaffinity="0" group="1" density="0" rgba="0.752941 0.752941 0.752941 1" mesh="head_yaw_link"/>
            <geom name="head_yaw_link_collision" type="mesh" rgba="0.752941 0.752941 0.752941 1" mesh="head_yaw_link"/>
            <body name="head_pitch_link" pos="0 0 0.082">
              <inertial pos="0.00374549 -0.00907247 0" quat="0.198873 0.678564 -0.198873 0.678564" mass="0.13405" diaginertia="4.48805e-05 4.20506e-05 2.82698e-05"/>
              <joint name="head_pitch" pos="0 0 0" axis="0 -1 0" range="-0.34 0.34" actuatorfrcrange="-4.8 4.8"/>
              <geom type="mesh" contype="0" conaffinity="0" group="1" density="0" rgba="0.752941 0.752941 0.752941 1" mesh="head_pitch_link"/>
              <geom name="head_pitch_link_collision" type="mesh" rgba="0.752941 0.752941 0.752941 1" mesh="head_pitch_link"/>
              <body name="head_roll_link" pos="0.026 -0.0005 0">
                <inertial pos="0.0255074 0.000498596 0.0936258" quat="0.992117 0.046517 0.116187 -0.00636454" mass="1.19844" diaginertia="0.0046481 0.00366936 0.00348896"/>
                <joint name="head_roll" pos="0 0 0" axis="1 0 0" range="-0.52 0.52" actuatorfrcrange="-4.8 4.8"/>
                <geom type="mesh" contype="0" conaffinity="0" group="1" density="0" rgba="0.752941 0.752941 0.752941 1" mesh="head_roll_link"/>
                <geom name="head_roll_link_collision" type="mesh" rgba="0.752941 0.752941 0.752941 1" mesh="head_roll_link"/>
              </body>
            </body>
          </body>
        </body>
      </body>
    </body>
  </worldbody>
  <contact>
    <exclude body1="base_link" body2="left_hip_roll_link"/>
    <exclude body1="base_link" body2="right_hip_roll_link"/>
    <exclude body1="left_elbow_pitch_link" body2="left_wrist_yaw_link"/>
    <exclude body1="right_elbow_pitch_link" body2="right_wrist_yaw_link"/>
    <exclude body1="waist_pitch_link" body2="left_shoulder_roll_link"/>
    <exclude body1="waist_pitch_link" body2="right_shoulder_roll_link"/>
    <exclude body1="head_yaw_link" body2="left_shoulder_pitch_link"/>
    <exclude body1="head_yaw_link" body2="right_shoulder_pitch_link"/>
  </contact>
  <sensor>
    <velocimeter name="imu_lin_vel" site="base_imu_site"/>
    <gyro name="imu_ang_vel" site="base_imu_site"/>
    <framequat name="base_link_orientation" objtype="site" objname="base_imu_site"/>
    <framepos name="base_link_position" objtype="site" objname="base_imu_site"/>
    <force name="left_ankle_force" site="left_ankle_site"/>
    <velocimeter name="left_ankle_velocity" site="left_ankle_site"/>
    <force name="right_ankle_force" site="right_ankle_site"/>
    <velocimeter name="right_ankle_velocity" site="right_ankle_site"/>
  </sensor>
</mujoco>
